Workbook

Sheet Misc.
A1: RunID | B1: RunDate | C1: Scenario | D1: Exagon_ver | E1: uSrvA_ver | F1: uSrvB_ver | G1: uSrvC_ver | H1: Saturated | I1: Target_TPS | J1: Effective_TPS | K1: Error_% | L1: Throt_max_% | M1: Throt_max_pod | N1: Core_sum_mCPU | O1: Lat_avg_ms
A2: simple-6.2.0-476,82,23-50-202605081142 | B2: 46150 | C2: Saga Simples | D2: dev-6.2.0-SNAPSHOT | E2: 3.12.0-rc476 | F2: 3.12.0-rc82 | G2: 3.12.0-rc23 | H2: =L2>20 -> FALSE | I2: 50 | J2: 50 | K2: 2.8117673e-12 | L2: =MAX('[1]Throttle_%'!B2:AE2) -> 17.117117 | M2: =SUM([2]Core_mCPU!B2:I2) -> 2349.2683 | N2: =SUM(Core_mCPU!B2:I2) -> 2349.2683 | O2: 34.8978
A3: simple-6.2.0-476,82,23-75-202605081207 | B3: 46150 | C3: Saga Simples | D3: dev-6.2.0-SNAPSHOT | E3: 3.12.0-rc476 | F3: 3.12.0-rc82 | G3: 3.12.0-rc23 | H3: =L3>20 -> FALSE | I3: 75 | J3: 74.959949 | K3: 0 | L3: =MAX('[1]Throttle_%'!B3:AE3) -> 16.141002 | M3: =SUM([2]Core_mCPU!B3:I3) -> 2783.2072 | N3: =SUM(Core_mCPU!B3:I3) -> 2783.2072 | O3: 37.588956
A4: simple-6.2.0-476,82,23-150-202605081232 | B4: 46150 | C4: Saga Simples | D4: dev-6.2.0-SNAPSHOT | E4: 3.12.0-rc476 | F4: 3.12.0-rc82 | G4: 3.12.0-rc23 | H4: =L4>20 -> FALSE | I4: 150 | J4: 144.78167 | K4: 2.8117626e-12 | L4: =MAX('[1]Throttle_%'!B4:AE4) -> 17.017438 | M4: =SUM([2]Core_mCPU!B4:I4) -> 3449.189 | N4: =SUM(Core_mCPU!B4:I4) -> 3449.189 | O4: 48.541385
A5: simple-6.2.0-476,82,23-200-202605081502 | B5: 46150 | C5: Saga Simples | D5: dev-6.2.0-SNAPSHOT | E5: 3.12.0-rc476 | F5: 3.12.0-rc82 | G5: 3.12.0-rc23 | H5: =L5>20 -> FALSE | I5: 200 | J5: 186.93667 | K5: 5.6234966e-12 | L5: =MAX('[1]Throttle_%'!B5:AE5) -> 17.34143 | M5: =SUM([2]Core_mCPU!B5:I5) -> 3819.8709 | N5: =SUM(Core_mCPU!B5:I5) -> 3819.8709 | O5: 54.352933
A6: simple-6.2.0-476,82,23-30000-202605190912 | B6: 46161 | C6: Saga Simples | D6: dev-6.2.0-SNAPSHOT | E6: 3.12.0-rc476 | F6: 3.12.0-rc82 | G6: 3.12.0-rc23 | H6: =L6>20 -> FALSE | I6: 30000 | J6: 5058.4543 | K6: 6.9723036e-09 | L6: =MAX('[1]Throttle_%'!B6:AE6) -> 16.990006 | M6: =SUM([2]Core_mCPU!B6:I6) -> 18111.049 | N6: =SUM(Core_mCPU!B6:I6) -> 18111.049 | O6: 78.208221
A7: rwro_consistent-6.2.0-506,112,52-1-202605202252 | B7: 46162 | C7: RW/RO Consistent | D7: dev-6.2.0-SNAPSHOT | E7: 3.12.0-rc506 | F7: 3.12.0-rc112 | G7: 3.12.0-rc52 | H7: =L7>20 -> FALSE | I7: 1 | J7: 1 | K7: 0 | L7: =MAX('[1]Throttle_%'!B7:AE7) -> 7.2689341 | M7: =SUM([2]Core_mCPU!B7:I7) -> 919.62133 | N7: =SUM(Core_mCPU!B7:I7) -> 919.62133 | O7: 40.888333
A8: rwro_consistent-6.2.0-506,112,52-300-202605210109 | B8: 46163 | C8: RW/RO Consistent | D8: dev-6.2.0-SNAPSHOT | E8: 3.12.0-rc506 | F8: 3.12.0-rc112 | G8: 3.12.0-rc52 | H8: =L8>20 -> FALSE | I8: 300 | J8: 300.00033 | K8: 2.810058e-12 | L8: =MAX('[1]Throttle_%'!B8:AE8) -> 8.1193982 | M8: =SUM([2]Core_mCPU!B8:I8) -> 9414.9418 | N8: =SUM(Core_mCPU!B8:I8) -> 9414.9418 | O8: 62.38182
A9: rwro_consistent-6.2.0-506,112,52-600-202605202315 | B9: 46162 | C9: RW/RO Consistent | D9: dev-6.2.0-SNAPSHOT | E9: 3.12.0-rc506 | F9: 3.12.0-rc112 | G9: 3.12.0-rc52 | H9: =L9>20 -> FALSE | I9: 600 | J9: 594.6594 | K9: 2.0705771e-11 | L9: =MAX('[1]Throttle_%'!B9:AE9) -> 7.7296569 | M9: =SUM([2]Core_mCPU!B9:I9) -> 13067.028 | N9: =SUM(Core_mCPU!B9:I9) -> 13067.028 | O9: 81.396371
A10: rwro_consistent-6.2.0-506,112,52-900-202605210132 | B10: 46163 | C10: RW/RO Consistent | D10: dev-6.2.0-SNAPSHOT | E10: 3.12.0-rc506 | F10: 3.12.0-rc112 | G10: 3.12.0-rc52 | H10: =L10>20 -> FALSE | I10: 900 | J10: 871.72397 | K10: 1.6017319e-10 | L10: =MAX('[1]Throttle_%'!B10:AE10) -> 8.2579065 | M10: =SUM([2]Core_mCPU!B10:I10) -> 14261.318 | N10: =SUM(Core_mCPU!B10:I10) -> 14261.318 | O10: 112.47112
A11: rwro_consistent-6.2.0-506,112,52-1200-202605202337 | B11: 46162 | C11: RW/RO Consistent | D11: dev-6.2.0-SNAPSHOT | E11: 3.12.0-rc506 | F11: 3.12.0-rc112 | G11: 3.12.0-rc52 | H11: =L11>20 -> FALSE | I11: 1200 | J11: 1156.1464 | K11: 4.7771135e-11 | L11: =MAX('[1]Throttle_%'!B11:AE11) -> 8.3261613 | M11: =SUM([2]Core_mCPU!B11:I11) -> 16651.678 | N11: =SUM(Core_mCPU!B11:I11) -> 16651.678 | O11: 112.00833
A12: rwro_consistent-6.2.0-506,112,52-1500-202605210155 | B12: 46163 | C12: RW/RO Consistent | D12: dev-6.2.0-SNAPSHOT | E12: 3.12.0-rc506 | F12: 3.12.0-rc112 | G12: 3.12.0-rc52 | H12: =L12>20 -> FALSE | I12: 1500 | J12: 1461.6805 | K12: 3.091059e-11 | L12: =MAX('[1]Throttle_%'!B12:AE12) -> 8.0091819 | M12: =SUM([2]Core_mCPU!B12:I12) -> 18770.521 | N12: =SUM(Core_mCPU!B12:I12) -> 18770.521 | O12: 117.10674
A13: rwro_consistent-6.2.0-506,112,52-1800-202605210000 | B13: 46163 | C13: RW/RO Consistent | D13: dev-6.2.0-SNAPSHOT | E13: 3.12.0-rc506 | F13: 3.12.0-rc112 | G13: 3.12.0-rc52 | H13: =L13>20 -> FALSE | I13: 1800 | J13: 1718.1606 | K13: 1.4050323e-11 | L13: =MAX('[1]Throttle_%'!B13:AE13) -> 8.4065779 | M13: =SUM([2]Core_mCPU!B13:I13) -> 19003.588 | N13: =SUM(Core_mCPU!B13:I13) -> 19003.588 | O13: 124.46892
... A61: parallel_command-6.3.0-523,127,67-3000-202606071211 | B61: 46180 | C61: Parallel Command | D61: dev-6.3.0-SNAPSHOT | E61: 3.13.0-rc523 | F61: 3.13.0-rc127 | G61: 3.13.0-rc67 | H61: =L61>20 -> FALSE | I61: 3000 | J61: 2944.0463 | K61: 1.4656048e-09 | L61: =MAX('[1]Throttle_%'!B61:AE61) -> 9.8080103 | M61: =SUM([2]Core_mCPU!B61:I61) -> 13761.022 | N61: =SUM(Core_mCPU!B61:I61) -> 13761.022 | O61: 78.564892
A62: get_by_prefix_1-6.3.0-528,133,73-1-202606200213 | B62: 46193 | C62: GetByPrefix 1 | D62: dev-6.3.0-SNAPSHOT | E62: 3.13.0-rc528 | F62: 3.13.0-rc133 | G62: 3.13.0-rc73 | H62: =L62>20 -> FALSE | I62: 1 | J62: 0.99999833 | K62: 0 | L62: =MAX('[1]Throttle_%'!B62:AE62) -> 10.271434 | M62: =SUM([2]Core_mCPU!B62:I62) -> 0 | N62: =SUM([1]Core_mCPU!B62:I62) -> 3146.1722 | O62: 12.173333
A63: get_by_prefix_1-6.3.0-528,133,73-300-202606200235 | B63: 46193 | C63: GetByPrefix 1 | D63: dev-6.3.0-SNAPSHOT | E63: 3.13.0-rc528 | F63: 3.13.0-rc133 | G63: 3.13.0-rc73 | H63: =L63>20 -> FALSE | I63: 300 | J63: 299.99983 | K63: 0 | L63: =MAX('[1]Throttle_%'!B63:AE63) -> 9.3704111 | M63: =SUM([2]Core_mCPU!B63:I63) -> 0 | N63: =SUM([1]Core_mCPU!B63:I63) -> 4594.6635 | O63: 6.3794291
A64: get_by_prefix_1-6.3.0-528,133,73-600-202606200257 | B64: 46193 | C64: GetByPrefix 1 | D64: dev-6.3.0-SNAPSHOT | E64: 3.13.0-rc528 | F64: 3.13.0-rc133 | G64: 3.13.0-rc73 | H64: =L64>20 -> FALSE | I64: 600 | J64: 599.99933 | K64: 0 | L64: =MAX('[1]Throttle_%'!B64:AE64) -> 10.674025 | M64: =SUM([2]Core_mCPU!B64:I64) -> 0 | N64: =SUM([1]Core_mCPU!B64:I64) -> 5643.0041 | O64: 5.952503
A65: get_by_prefix_1-6.3.0-528,133,73-900-202606200320 | B65: 46193 | C65: GetByPrefix 1 | D65: dev-6.3.0-SNAPSHOT | E65: 3.13.0-rc528 | F65: 3.13.0-rc133 | G65: 3.13.0-rc73 | H65: =L65>20 -> FALSE | I65: 900 | J65: 899.99933 | K65: 0 | L65: =MAX('[1]Throttle_%'!B65:AE65) -> 9.6830435 | M65: =SUM([2]Core_mCPU!B65:I65) -> 0 | N65: =SUM([1]Core_mCPU!B65:I65) -> 6560.2447 | O65: 5.7423394
A66: get_by_prefix_1-6.3.0-528,133,73-1200-202606200342 | B66: 46193 | C66: GetByPrefix 1 | D66: dev-6.3.0-SNAPSHOT | E66: 3.13.0-rc528 | F66: 3.13.0-rc133 | G66: 3.13.0-rc73 | H66: =L66>20 -> FALSE | I66: 1200 | J66: 1200.002 | K66: 0 | L66: =MAX('[1]Throttle_%'!B66:AE66) -> 9.5890859 | M66: =SUM([2]Core_mCPU!B66:I66) -> 0 | N66: =SUM([1]Core_mCPU!B66:I66) -> 7011.4108 | O66: 5.6999025
A67: get_by_prefix_1-6.3.0-528,133,73-1500-202606200404 | B67: 46193 | C67: GetByPrefix 1 | D67: dev-6.3.0-SNAPSHOT | E67: 3.13.0-rc528 | F67: 3.13.0-rc133 | G67: 3.13.0-rc73 | H67: =L67>20 -> FALSE | I67: 1500 | J67: 1500.0017 | K67: 0 | L67: =MAX('[1]Throttle_%'!B67:AE67) -> 9.9367295 | M67: =SUM([2]Core_mCPU!B67:I67) -> 0 | N67: =SUM([1]Core_mCPU!B67:I67) -> 7695.68 | O67: 5.9391914
A68: get_by_prefix_1-6.3.0-528,133,73-1800-202606200426 | B68: 46193 | C68: GetByPrefix 1 | D68: dev-6.3.0-SNAPSHOT | E68: 3.13.0-rc528 | F68: 3.13.0-rc133 | G68: 3.13.0-rc73 | H68: =L68>20 -> FALSE | I68: 1800 | J68: 1799.9707 | K68: 0 | L68: =MAX('[1]Throttle_%'!B68:AE68) -> 9.3686765 | M68: =SUM([2]Core_mCPU!B68:I68) -> 0 | N68: =SUM([1]Core_mCPU!B68:I68) -> 8100.3104 | O68: 6.5259023
A69: get_by_prefix_1-6.3.0-528,133,73-2100-202606200448 | B69: 46193 | C69: GetByPrefix 1 | D69: dev-6.3.0-SNAPSHOT | E69: 3.13.0-rc528 | F69: 3.13.0-rc133 | G69: 3.13.0-rc73 | H69: =L69>20 -> FALSE | I69: 2100 | J69: 2100.0062 | K69: 0 | L69: =MAX('[1]Throttle_%'!B69:AE69) -> 10.45333 | M69: =SUM([2]Core_mCPU!B69:I69) -> 0 | N69: =SUM([1]Core_mCPU!B69:I69) -> 8764.2602 | O69: 7.2148637
A70: get_by_prefix_1-6.3.0-528,133,73-2400-202606200511 | B70: 46193 | C70: GetByPrefix 1 | D70: dev-6.3.0-SNAPSHOT | E70: 3.13.0-rc528 | F70: 3.13.0-rc133 | G70: 3.13.0-rc73 | H70: =L70>20 -> FALSE | I70: 2400 | J70: 2400.0004 | K70: 0 | L70: =MAX('[1]Throttle_%'!B70:AE70) -> 10.022736 | M70: =SUM([2]Core_mCPU!B70:I70) -> 0 | N70: =SUM([1]Core_mCPU!B70:I70) -> 9377.4258 | O70: 9.1507372
A71: get_by_prefix_1-6.3.0-528,133,73-2700-202606200532 | B71: 46193 | C71: GetByPrefix 1 | D71: dev-6.3.0-SNAPSHOT | E71: 3.13.0-rc528 | F71: 3.13.0-rc133 | G71: 3.13.0-rc73 | H71: =L71>20 -> FALSE | I71: 2700 | J71: 2699.9573 | K71: 0 | L71: =MAX('[1]Throttle_%'!B71:AE71) -> 10.125924 | M71: =SUM([2]Core_mCPU!B71:I71) -> 0 | N71: =SUM([1]Core_mCPU!B71:I71) -> 9845.8415 | O71: 12.242844
A72: get_by_prefix_1-6.3.0-528,133,73-3000-202606200555 | B72: 46193 | C72: GetByPrefix 1 | D72: dev-6.3.0-SNAPSHOT | E72: 3.13.0-rc528 | F72: 3.13.0-rc133 | G72: 3.13.0-rc73 | H72: =L72>20 -> FALSE | I72: 3000 | J72: 3001.5611 | K72: 2.5739855e-08 | L72: =MAX('[1]Throttle_%'!B72:AE72) -> 10.8189 | M72: =SUM([2]Core_mCPU!B72:I72) -> 0 | N72: =SUM([1]Core_mCPU!B72:I72) -> 10415.351 | O72: 15.520812
A73: get_by_prefix_27-6.3.0-528,133,73-1-202606200832 | B73: 46193 | C73: GetByPrefix 27 | D73: dev-6.3.0-SNAPSHOT | E73: 3.13.0-rc528 | F73: 3.13.0-rc133 | G73: 3.13.0-rc73 | H73: =L73>20 -> FALSE | I73: 1 | J73: 1 | K73: 0 | L73: =MAX('[1]Throttle_%'!B73:AE73) -> 9.8188073 | M73: =SUM([2]Core_mCPU!B73:I73) -> 0 | N73: =SUM([1]Core_mCPU!B73:I73) -> 3210.7688 | O73: 12.316667
... A120: choreography-6.3.0-528,133,73-3000-202606261826 | B120: 46199 | C120: Coreografia | D120: dev-6.3.0-SNAPSHOT | E120: 3.13.0-rc528 | F120: 3.13.0-rc133 | G120: 3.13.0-rc73 | H120: =L120>20 -> FALSE | I120: 3000 | J120: 2781.5533 | K120: 2.0757418e-10 | L120: =MAX('[1]Throttle_%'!B120:AE120) -> 9.8226462 | M120: =SUM([2]Core_mCPU!B120:I120) -> 0 | N120: =SUM([1]Core_mCPU!B120:I120) -> 12756.233 | O120: 56.965924

Sheet Core_mCPU
A1: RunID | B1: im | C1: kafka | D1: orch-a | E1: part-b | F1: part-c | G1: rf | H1: mongo | I1: redis | J1: kafka-0 | K1: kafka-1 | L1: kafka-2 | M1: orch-a-0 | N1: orch-a-1 | O1: part-b-0 | P1: part-c-0 | Q1: rf-a-0 | R1: rf-b-0 | S1: rf-c-0 | T1: mongo-a-0 | U1: mongo-a-1 | V1: mongo-b-0 | W1: mongo-b-1 | X1: mongo-c-0 | Y1: mongo-c-1 | Z1: redis-a-0 | AA1: redis-a-1 | AB1: redis-b-0 | AC1: redis-b-1 | AD1: redis-c-0 | AE1: redis-c-1
A2: simple-6.2.0-476,82,23-50-202605081142 | B2: 31.874894 | C2: 1024.8925 | D2: 244.75515 | E2: 128.65741 | F2: 122.53314 | G2: 31.915929 | H2: 595.30587 | I2: 169.33336 | J2: - | K2: - | L2: - | M2: - | N2: - | O2: - | P2: - | Q2: - | R2: - | S2: - | T2: - | U2: - | V2: - | W2: - | X2: - | Y2: - | Z2: - | AA2: - | AB2: - | AC2: - | AD2: - | AE2: -
A3: simple-6.2.0-476,82,23-75-202605081207 | B3: 47.912627 | C3: 1299.9969 | D3: 316.73267 | E3: 178.0866 | F3: 174.67388 | G3: 37.53062 | H3: 563.84677 | I3: 164.42716 | J3: - | K3: - | L3: - | M3: - | N3: - | O3: - | P3: - | Q3: - | R3: - | S3: - | T3: - | U3: - | V3: - | W3: - | X3: - | Y3: - | Z3: - | AA3: - | AB3: - | AC3: - | AD3: - | AE3: -
A4: simple-6.2.0-476,82,23-150-202605081232 | B4: 93.123078 | C4: 1524.5983 | D4: 524.32554 | E4: 261.26952 | F4: 266.29078 | G4: 55.191257 | H4: 557.24361 | I4: 167.14693 | J4: - | K4: - | L4: - | M4: - | N4: - | O4: - | P4: - | Q4: - | R4: - | S4: - | T4: - | U4: - | V4: - | W4: - | X4: - | Y4: - | Z4: - | AA4: - | AB4: - | AC4: - | AD4: - | AE4: -
A5: simple-6.2.0-476,82,23-200-202605081502 | B5: 140.36784 | C5: 1622.1005 | D5: 626.07856 | E5: 321.32787 | F5: 326.26125 | G5: 36.662588 | H5: 574.9755 | I5: 172.09674 | J5: - | K5: - | L5: - | M5: - | N5: - | O5: - | P5: - | Q5: - | R5: - | S5: - | T5: - | U5: - | V5: - | W5: - | X5: - | Y5: - | Z5: - | AA5: - | AB5: - | AC5: - | AD5: - | AE5: -
A6: simple-6.2.0-476,82,23-30000-202605190912 | B6: 554.24326 | C6: 4136.5275 | D6: 6532.7363 | E6: 3026.7838 | F6: 2918.9354 | G6: 31.654581 | H6: 575.41017 | I6: 334.75777 | J6: - | K6: - | L6: - | M6: - | N6: - | O6: - | P6: - | Q6: - | R6: - | S6: - | T6: - | U6: - | V6: - | W6: - | X6: - | Y6: - | Z6: - | AA6: - | AB6: - | AC6: - | AD6: - | AE6: -
A7: rwro_consistent-6.2.0-506,112,52-1-202605202252 | B7: 6.4003346 | C7: 201.6573 | D7: 10.278712 | E7: 15.717066 | F7: 17.979111 | G7: 27.771282 | H7: 499.35977 | I7: 140.45776 | J7: - | K7: - | L7: - | M7: - | N7: - | O7: - | P7: - | Q7: 10.325124 | R7: 7.7959586 | S7: 9.6501995 | T7: - | U7: - | V7: - | W7: - | X7: - | Y7: - | Z7: - | AA7: - | AB7: - | AC7: - | AD7: - | AE7: -
A8: rwro_consistent-6.2.0-506,112,52-300-202605210109 | B8: 219.0642 | C8: 2590.5002 | D8: 1415.0676 | E8: 615.85104 | F8: 698.70366 | G8: 653.149 | H8: 3009.72 | I8: 212.88621 | J8: - | K8: - | L8: - | M8: - | N8: - | O8: - | P8: - | Q8: 181.82502 | R8: 183.17776 | S8: 288.14622 | T8: - | U8: - | V8: - | W8: - | X8: - | Y8: - | Z8: - | AA8: - | AB8: - | AC8: - | AD8: - | AE8: -
A9: rwro_consistent-6.2.0-506,112,52-600-202605202315 | B9: 212.40083 | C9: 3219.3938 | D9: 2253.6134 | E9: 842.2421 | F9: 996.38074 | G9: 1264.1928 | H9: 4044.8854 | I9: 233.91895 | J9: - | K9: - | L9: - | M9: - | N9: - | O9: - | P9: - | Q9: 609.06146 | R9: 282.64972 | S9: 372.48163 | T9: - | U9: - | V9: - | W9: - | X9: - | Y9: - | Z9: - | AA9: - | AB9: - | AC9: - | AD9: - | AE9: -
A10: rwro_consistent-6.2.0-506,112,52-900-202605210132 | B10: 265.19648 | C10: 3479.7179 | D10: 2359.9951 | E10: 1056.1145 | F10: 1204.3825 | G10: 1335.4747 | H10: 4302.024 | I10: 258.41304 | J10: - | K10: - | L10: - | M10: - | N10: - | O10: - | P10: - | Q10: 661.07289 | R10: 280.46991 | S10: 393.93186 | T10: - | U10: - | V10: - | W10: - | X10: - | Y10: - | Z10: - | AA10: - | AB10: - | AC10: - | AD10: - | AE10: -
A11: rwro_consistent-6.2.0-506,112,52-1200-202605202337 | B11: 315.55468 | C11: 4084.2104 | D11: 2771.4223 | E11: 1313.3507 | F11: 1638.1741 | G11: 1399.2565 | H11: 4850.2517 | I11: 279.45715 | J11: - | K11: - | L11: - | M11: - | N11: - | O11: - | P11: - | Q11: 691.99595 | R11: 251.96547 | S11: 455.29512 | T11: - | U11: - | V11: - | W11: - | X11: - | Y11: - | Z11: - | AA11: - | AB11: - | AC11: - | AD11: - | AE11: -
A12: rwro_consistent-6.2.0-506,112,52-1500-202605210155 | B12: 338.51044 | C12: 4523.1798 | D12: 3651.8869 | E12: 1536.2857 | F12: 1752.1367 | G12: 1530.3688 | H12: 5143.8043 | I12: 294.34789 | J12: - | K12: - | L12: - | M12: - | N12: - | O12: - | P12: - | Q12: 726.20967 | R12: 290.58847 | S12: 513.57066 | T12: - | U12: - | V12: - | W12: - | X12: - | Y12: - | Z12: - | AA12: - | AB12: - | AC12: - | AD12: - | AE12: -
A13: rwro_consistent-6.2.0-506,112,52-1800-202605210000 | B13: 386.79613 | C13: 4570.4284 | D13: 3448.686 | E13: 1648.9362 | F13: 1831.8688 | G13: 1530.1666 | H13: 5282.1088 | I13: 304.59727 | J13: - | K13: - | L13: - | M13: - | N13: - | O13: - | P13: - | Q13: 758.08899 | R13: 255.23917 | S13: 516.83841 | T13: - | U13: - | V13: - | W13: - | X13: - | Y13: - | Z13: - | AA13: - | AB13: - | AC13: - | AD13: - | AE13: -
A14: rwro_consistent-6.2.0-506,112,52-2100-202605210218 | B14: 397.64209 | C14: 4729.8249 | D14: 4336.0169 | E14: 1738.2043 | F14: 2270.6243 | G14: 1648.7343 | H14: 5670.4087 | I14: 337.29482 | J14: - | K14: - | L14: - | M14: - | N14: - | O14: - | P14: - | Q14: 754.44269 | R14: 292.34564 | S14: 601.94595 | T14: - | U14: - | V14: - | W14: - | X14: - | Y14: - | Z14: - | AA14: - | AB14: - | AC14: - | AD14: - | AE14: -
A15: rwro_consistent-6.2.0-506,112,52-2400-202605210023 | B15: 429.38757 | C15: 4883.8067 | D15: 4911.0273 | E15: 1950.2084 | F15: 2527.3628 | G15: 1704.4443 | H15: 6094.4856 | I15: 350.96465 | J15: - | K15: - | L15: - | M15: - | N15: - | O15: - | P15: - | Q15: 771.84798 | R15: 286.82414 | S15: 645.77223 | T15: - | U15: - | V15: - | W15: - | X15: - | Y15: - | Z15: - | AA15: - | AB15: - | AC15: - | AD15: - | AE15: -
A16: rwro_consistent-6.2.0-506,112,52-2700-202605210241 | B16: 472.37676 | C16: 4719.7713 | D16: 5190.4461 | E16: 1965.6659 | F16: 2615.5991 | G16: 1696.9978 | H16: 6225.8234 | I16: 362.71946 | J16: - | K16: - | L16: - | M16: - | N16: - | O16: - | P16: - | Q16: 771.04023 | R16: 284.89221 | S16: 641.06537 | T16: - | U16: - | V16: - | W16: - | X16: - | Y16: - | Z16: - | AA16: - | AB16: - | AC16: - | AD16: - | AE16: -
A17: rwro_consistent-6.2.0-506,112,52-3000-202605210046 | B17: 473.64509 | C17: 4890.7012 | D17: 5563.8919 | E17: 2221.6056 | F17: 2816.9225 | G17: 1762.317 | H17: 6752.4978 | I17: 375.09576 | J17: - | K17: - | L17: - | M17: - | N17: - | O17: - | P17: - | Q17: 776.35615 | R17: 309.80686 | S17: 676.15395 | T17: - | U17: - | V17: - | W17: - | X17: - | Y17: - | Z17: - | AA17: - | AB17: - | AC17: - | AD17: - | AE17: -
A18: rwro_none-6.2.0-506,112,52-1-202605201840 | B18: 6.6021572 | C18: 218.42178 | D18: 17.277941 | E18: 15.649888 | F18: 19.692108 | G18: 23.731151 | H18: 477.23376 | I18: 137.32616 | J18: - | K18: - | L18: - | M18: - | N18: - | O18: - | P18: - | Q18: 10.201846 | R18: 7.4780274 | S18: 6.0512777 | T18: - | U18: - | V18: - | W18: - | X18: - | Y18: - | Z18: - | AA18: - | AB18: - | AC18: - | AD18: - | AE18: -
... A50: rwro_optimized_heap-6.2.0-506,112,52-3000-202605211228 | B50: 458.9567 | C50: 5035.4331 | D50: 5328.3585 | E50: 2303.0394 | F50: 2634.0348 | G50: 1368.236 | H50: 5937.9477 | I50: 332.76067 | J50: - | K50: - | L50: - | M50: - | N50: - | O50: - | P50: - | Q50: 769.92023 | R50: 311.01694 | S50: 287.29885 | T50: - | U50: - | V50: - | W50: - | X50: - | Y50: - | Z50: - | AA50: - | AB50: - | AC50: - | AD50: - | AE50: -
A51: parallel_command-6.3.0-523,127,67-1-202606070759 | B51: 10.590481 | C51: 203.93185 | D51: 26.536491 | E51: 16.291411 | F51: 17.710055 | G51: 22.211114 | H51: 552.58272 | I51: 141.44131 | J51: 97.447001 | K51: 58.095542 | L51: 48.389306 | M51: 26.536491 | N51: - | O51: 16.291411 | P51: 17.710055 | Q51: 10.384911 | R51: 5.7455992 | S51: 6.080604 | T51: 69.657644 | U51: 119.92996 | V51: 63.237077 | W51: 108.19779 | X51: 82.002653 | Y51: 109.5576 | Z51: 20.45871 | AA51: 26.482906 | AB51: 20.188314 | AC51: 27.904076 | AD51: 20.361545 | AE51: 26.045755
A52: parallel_command-6.3.0-523,127,67-300-202606070824 | B52: 125.60245 | C52: 2135.1253 | D52: 771.66872 | E52: 455.05115 | F52: 324.05617 | G52: 39.231876 | H52: 539.32755 | I52: 172.60971 | J52: 606.46529 | K52: 605.33918 | L52: 923.32082 | M52: 771.66872 | N52: - | O52: 455.05115 | P52: 324.05617 | Q52: 21.210135 | R52: 5.8935561 | S52: 12.128185 | T52: 91.255204 | U52: 100.94282 | V52: 80.769948 | W52: 111.98458 | X52: 64.517119 | Y52: 89.857878 | Z52: 31.845723 | AA52: 37.653972 | AB52: 22.022261 | AC52: 30.939055 | AD52: 22.831691 | AE52: 27.317004
A53: parallel_command-6.3.0-523,127,67-600-202606070849 | B53: 170.01361 | C53: 2432.7316 | D53: 1285.7284 | E53: 733.13093 | F53: 514.89 | G53: 36.87964 | H53: 555.16506 | I53: 190.4561 | J53: 661.70014 | K53: 1099.4969 | L53: 671.5346 | M53: 1285.7284 | N53: - | O53: 733.13093 | P53: 514.89 | Q53: 13.140321 | R53: 10.371847 | S53: 13.367473 | T53: 89.140621 | U53: 78.104296 | V53: 94.015403 | W53: 111.08499 | X53: 93.32816 | Y53: 89.491591 | Z53: 41.651449 | AA53: 40.586619 | AB53: 22.534137 | AC53: 29.570211 | AD53: 23.799067 | AE53: 32.314614
A54: parallel_command-6.3.0-523,127,67-900-202606070914 | B54: 208.9976 | C54: 3071.9773 | D54: 1682.8649 | E54: 939.32739 | F54: 706.55095 | G54: 28.344815 | H54: 566.08975 | I54: 199.68048 | J54: 984.73241 | K54: 912.92042 | L54: 1174.3245 | M54: 1682.8649 | N54: - | O54: 939.32739 | P54: 706.55095 | Q54: 13.365449 | R54: 6.4534635 | S54: 8.5259026 | T54: 76.396239 | U54: 93.256322 | V54: 79.122858 | W54: 101.20252 | X54: 102.99662 | Y54: 113.11518 | Z54: 47.864508 | AA54: 45.943821 | AB54: 22.991884 | AC54: 30.225733 | AD54: 23.729551 | AE54: 28.924984
A55: parallel_command-6.3.0-523,127,67-1200-202606070939 | B55: 261.27211 | C55: 3251.5989 | D55: 2182.1927 | E55: 1198.7399 | F55: 946.78812 | G55: 38.149296 | H55: 529.59323 | I55: 205.66302 | J55: 1070.4878 | K55: 1007.7842 | L55: 1173.3269 | M55: 2182.1927 | N55: - | O55: 1198.7399 | P55: 946.78812 | Q55: 21.260577 | R55: 10.455498 | S55: 6.433221 | T55: 90.424273 | U55: 120.1497 | V55: 77.861794 | W55: 79.690016 | X55: 71.884195 | Y55: 89.583257 | Z55: 53.258581 | AA55: 47.424231 | AB55: 22.815318 | AC55: 30.087763 | AD55: 23.213413 | AE55: 28.863719
A56: parallel_command-6.3.0-523,127,67-1500-202606071005 | B56: 305.20733 | C56: 3369.7357 | D56: 2318.0722 | E56: 1411.8254 | F56: 1069.5876 | G56: 28.671304 | H56: 580.45328 | I56: 220.55601 | J56: 1047.293 | K56: 1163.9897 | L56: 1158.453 | M56: 2318.0722 | N56: - | O56: 1411.8254 | P56: 1069.5876 | Q56: 12.794271 | R56: 10.180154 | S56: 5.6968799 | T56: 83.297386 | U56: 97.823142 | V56: 84.580586 | W56: 106.46726 | X56: 87.442018 | Y56: 120.84289 | Z56: 59.391644 | AA56: 55.072741 | AB56: 23.149184 | AC56: 30.607183 | AD56: 23.489043 | AE56: 28.846213
A57: parallel_command-6.3.0-523,127,67-1800-202606071030 | B57: 347.12753 | C57: 3630.2021 | D57: 2662.8572 | E57: 1597.1348 | F57: 1236.8596 | G57: 32.941563 | H57: 587.85816 | I57: 228.7803 | J57: 1251.6708 | K57: 1189.8846 | L57: 1188.6467 | M57: 2662.8572 | N57: - | O57: 1597.1348 | P57: 1236.8596 | Q57: 14.062142 | R57: 10.195672 | S57: 8.6837496 | T57: 67.363497 | U57: 117.3596 | V57: 79.703431 | W57: 128.21129 | X57: 91.815836 | Y57: 103.4045 | Z57: 66.22932 | AA57: 57.228969 | AB57: 25.318188 | AC57: 28.737707 | AD57: 23.725718 | AE57: 27.540401
A58: parallel_command-6.3.0-523,127,67-2100-202606071055 | B58: 388.67634 | C58: 3649.4768 | D58: 2988.5007 | E58: 1696.3908 | F58: 1331.9326 | G58: 38.357693 | H58: 595.09913 | I58: 238.20605 | J58: 1249.5843 | K58: 1191.2246 | L58: 1208.6678 | M58: 2988.5007 | N58: - | O58: 1696.3908 | P58: 1331.9326 | Q58: 16.218845 | R58: 15.756418 | S58: 6.38243 | T58: 99.319831 | U58: 99.859635 | V58: 88.239664 | W58: 104.12209 | X58: 95.552304 | Y58: 108.00561 | Z58: 71.918856 | AA58: 58.207551 | AB58: 25.591764 | AC58: 30.073215 | AD58: 23.756273 | AE58: 28.658387
A59: parallel_command-6.3.0-523,127,67-2400-202606071120 | B59: 388.03676 | C59: 3940.5861 | D59: 3343.7312 | E59: 2050.4948 | F59: 1461.7063 | G59: 32.182363 | H59: 529.64439 | I59: 249.48255 | J59: 1258.5514 | K59: 1423.6669 | L59: 1258.3678 | M59: 3343.7312 | N59: - | O59: 2050.4948 | P59: 1461.7063 | Q59: 14.146379 | R59: 9.62761 | S59: 8.4083738 | T59: 68.708589 | U59: 115.62785 | V59: 68.414965 | W59: 93.040326 | X59: 79.454312 | Y59: 104.39834 | Z59: 77.269281 | AA59: 65.236949 | AB59: 23.474143 | AC59: 28.169248 | AD59: 23.279326 | AE59: 32.053604
A60: parallel_command-6.3.0-523,127,67-2700-202606071146 | B60: 404.38216 | C60: 4019.4916 | D60: 3789.7134 | E60: 2189.2547 | F60: 1703.3793 | G60: 28.93567 | H60: 535.94188 | I60: 258.20081 | J60: 1432.9635 | K60: 1201.5091 | L60: 1385.019 | M60: 3789.7134 | N60: - | O60: 2189.2547 | P60: 1703.3793 | Q60: 14.260559 | R60: 9.356348 | S60: 5.318763 | T60: 93.804476 | U60: 83.092722 | V60: 90.344967 | W60: 99.067694 | X60: 78.148968 | Y60: 91.483052 | Z60: 84.476983 | AA60: 69.960976 | AB60: 23.873568 | AC60: 28.145938 | AD60: 22.358697 | AE60: 29.384645
A61: parallel_command-6.3.0-523,127,67-3000-202606071211 | B61: 449.66486 | C61: 4188.8872 | D61: 4158.2905 | E61: 2255.5108 | F61: 1875.5614 | G61: 28.64904 | H61: 536.41158 | I61: 268.04669 | J61: 1311.7236 | K61: 1504.4373 | L61: 1372.7263 | M61: 4158.2905 | N61: - | O61: 2255.5108 | P61: 1875.5614 | Q61: 11.442773 | R61: 10.06514 | S61: 7.1411271 | T61: 82.654301 | U61: 106.21688 | V61: 61.03483 | W61: 121.46875 | X61: 66.541815 | Y61: 98.495006 | Z61: 86.36774 | AA61: 72.677229 | AB61: 24.081782 | AC61: 28.849087 | AD61: 24.853899 | AE61: 31.216954
A62: get_by_prefix_1-6.3.0-528,133,73-1-202606200213 | B62: 12.602015 | C62: 1661.8083 | D62: 172.43846 | E62: 113.12823 | F62: 107.12706 | G62: 376.14668 | H62: 545.47946 | I62: 157.44205 | J62: 486.85105 | K62: 717.60561 | L62: 457.3516 | M62: 172.43846 | N62: - | O62: 113.12823 | P62: 107.12706 | Q62: 188.28529 | R62: 94.344673 | S62: 93.516722 | T62: 75.718399 | U62: 103.54915 | V62: 67.711987 | W62: 105.38619 | X62: 84.371602 | Y62: 108.74214 | Z62: 30.408058 | AA62: 31.949504 | AB62: 19.936283 | AC62: 26.12114 | AD62: 21.255374 | AE62: 27.771688
... A120: choreography-6.3.0-528,133,73-3000-202606261826 | B120: 346.99278 | C120: 4390.8566 | D120: 3680.9887 | E120: 1764.5268 | F120: 1656.9774 | G120: 25.835547 | H120: 545.46946 | I120: 344.58604 | J120: 1745.3645 | K120: 1326.814 | L120: 1318.6781 | M120: 3680.9887 | N120: - | O120: 1764.5268 | P120: 1656.9774 | Q120: 11.077908 | R120: 7.1446287 | S120: 7.6130099 | T120: 96.485683 | U120: 72.675719 | V120: 114.93021 | W120: 102.41799 | X120: 80.564868 | Y120: 78.39498 | Z120: 120.03905 | AA120: 93.389742 | AB120: 27.403704 | AC120: 37.339147 | AD120: 27.973895 | AE120: 38.440505

Sheet Memory_MB
A1: RunID | B1: im | C1: kafka | D1: orch-a | E1: part-b | F1: part-c | G1: rf | H1: mongo | I1: redis | J1: kafka-0 | K1: kafka-1 | L1: kafka-2 | M1: orch-a-0 | N1: orch-a-1 | O1: part-b-0 | P1: part-c-0 | Q1: rf-a-0 | R1: rf-b-0 | S1: rf-c-0 | T1: mongo-a-0 | U1: mongo-a-1 | V1: mongo-b-0 | W1: mongo-b-1 | X1: mongo-c-0 | Y1: mongo-c-1 | Z1: redis-a-0 | AA1: redis-a-1 | AB1: redis-b-0 | AC1: redis-b-1 | AD1: redis-c-0 | AE1: redis-c-1
A2: simple-6.2.0-476,82,23-50-202605081142 | B2: 259.22355 | C2: 9503.5269 | D2: 1776.0379 | E2: 1753.5345 | F2: 1667.4324 | G2: 1512.2637 | H2: 1301.504 | I2: 68.653056 | J2: - | K2: - | L2: - | M2: - | N2: - | O2: - | P2: - | Q2: - | R2: - | S2: - | T2: - | U2: - | V2: - | W2: - | X2: - | Y2: - | Z2: - | AA2: - | AB2: - | AC2: - | AD2: - | AE2: -
A3: simple-6.2.0-476,82,23-75-202605081207 | B3: 268.03814 | C3: 9079.0298 | D3: 1833.3778 | E3: 1858.8672 | F3: 1745.5186 | G3: 1499.8118 | H3: 1149.0509 | I3: 68.501504 | J3: - | K3: - | L3: - | M3: - | N3: - | O3: - | P3: - | Q3: - | R3: - | S3: - | T3: - | U3: - | V3: - | W3: - | X3: - | Y3: - | Z3: - | AA3: - | AB3: - | AC3: - | AD3: - | AE3: -
A4: simple-6.2.0-476,82,23-150-202605081232 | B4: 698.54003 | C4: 11166.409 | D4: 1806.6924 | E4: 1811.9475 | F4: 1745.2605 | G4: 1496.3876 | H4: 1138.348 | I4: 68.784128 | J4: - | K4: - | L4: - | M4: - | N4: - | O4: - | P4: - | Q4: - | R4: - | S4: - | T4: - | U4: - | V4: - | W4: - | X4: - | Y4: - | Z4: - | AA4: - | AB4: - | AC4: - | AD4: - | AE4: -
A5: simple-6.2.0-476,82,23-200-202605081502 | B5: 509.25978 | C5: 9852.375 | D5: 1810.5917 | E5: 1818.1243 | F5: 1777.111 | G5: 1546.625 | H5: 1150.7425 | I5: 68.780032 | J5: - | K5: - | L5: - | M5: - | N5: - | O5: - | P5: - | Q5: - | R5: - | S5: - | T5: - | U5: - | V5: - | W5: - | X5: - | Y5: - | Z5: - | AA5: - | AB5: - | AC5: - | AD5: - | AE5: -
A6: simple-6.2.0-476,82,23-30000-202605190912 | B6: 656.01946 | C6: 23214.182 | D6: 15780.033 | E6: 8060.0924 | F6: 8012.7099 | G6: 1759.7727 | H6: 1277.8742 | I6: 66.400256 | J6: - | K6: - | L6: - | M6: - | N6: - | O6: - | P6: - | Q6: - | R6: - | S6: - | T6: - | U6: - | V6: - | W6: - | X6: - | Y6: - | Z6: - | AA6: - | AB6: - | AC6: - | AD6: - | AE6: -
A7: rwro_consistent-6.2.0-506,112,52-1-202605202252 | B7: 312.57395 | C7: 15002.673 | D7: 1443.6393 | E7: 1491.7591 | F7: 1398.3293 | G7: 2817.2943 | H7: 1238.6714 | I7: 67.66592 | J7: - | K7: - | L7: - | M7: - | N7: - | O7: - | P7: - | Q7: 922.16934 | R7: 904.52787 | S7: 990.59712 | T7: - | U7: - | V7: - | W7: - | X7: - | Y7: - | Z7: - | AA7: - | AB7: - | AC7: - | AD7: - | AE7: -
A8: rwro_consistent-6.2.0-506,112,52-300-202605210109 | B8: 751.07123 | C8: 22594.839 | D8: 8008.0036 | E8: 8069.46 | F8: 8050.5078 | G8: 7744.6431 | H8: 3135.6191 | I8: 69.660672 | J8: - | K8: - | L8: - | M8: - | N8: - | O8: - | P8: - | Q8: 4985.4833 | R8: 1373.6468 | S8: 1385.513 | T8: - | U8: - | V8: - | W8: - | X8: - | Y8: - | Z8: - | AA8: - | AB8: - | AC8: - | AD8: - | AE8: -
A9: rwro_consistent-6.2.0-506,112,52-600-202605202315 | B9: 795.93882 | C9: 23985.525 | D9: 9350.4061 | E9: 8094.5316 | F9: 8041.0542 | G9: 8396.6403 | H9: 4210.0941 | I9: 69.541888 | J9: - | K9: - | L9: - | M9: - | N9: - | O9: - | P9: - | Q9: 5015.081 | R9: 1614.3237 | S9: 1767.2356 | T9: - | U9: - | V9: - | W9: - | X9: - | Y9: - | Z9: - | AA9: - | AB9: - | AC9: - | AD9: - | AE9: -
A10: rwro_consistent-6.2.0-506,112,52-900-202605210132 | B10: 908.22246 | C10: 31934.431 | D10: 12510.286 | E10: 8071.8356 | F10: 8063.0907 | G10: 10784.6 | H10: 4425.6502 | I10: 69.640192 | J10: - | K10: - | L10: - | M10: - | N10: - | O10: - | P10: - | Q10: 4996.6244 | R10: 1597.313 | S10: 4190.6627 | T10: - | U10: - | V10: - | W10: - | X10: - | Y10: - | Z10: - | AA10: - | AB10: - | AC10: - | AD10: - | AE10: -
A11: rwro_consistent-6.2.0-506,112,52-1200-202605202337 | B11: 1043.5052 | C11: 32022.913 | D11: 12163.629 | E11: 8076.5952 | F11: 8069.6812 | G11: 8420.1021 | H11: 5013.2623 | I11: 68.698112 | J11: - | K11: - | L11: - | M11: - | N11: - | O11: - | P11: - | Q11: 4999.1762 | R11: 1582.678 | S11: 1838.2479 | T11: - | U11: - | V11: - | W11: - | X11: - | Y11: - | Z11: - | AA11: - | AB11: - | AC11: - | AD11: - | AE11: -
A12: rwro_consistent-6.2.0-506,112,52-1500-202605210155 | B12: 1238.2904 | C12: 32866.394 | D12: 14116.438 | E12: 8126.1527 | F12: 8064.6144 | G12: 8500.1216 | H12: 5468.3034 | I12: 69.054464 | J12: - | K12: - | L12: - | M12: - | N12: - | O12: - | P12: - | Q12: 5013.4508 | R12: 1609.6748 | S12: 1876.9961 | T12: - | U12: - | V12: - | W12: - | X12: - | Y12: - | Z12: - | AA12: - | AB12: - | AC12: - | AD12: - | AE12: -
A13: rwro_consistent-6.2.0-506,112,52-1800-202605210000 | B13: 591.45421 | C13: 32159.535 | D13: 15116.73 | E13: 8079.2084 | F13: 8087.466 | G13: 8381.9233 | H13: 6424.8873 | I13: 69.255168 | J13: - | K13: - | L13: - | M13: - | N13: - | O13: - | P13: - | Q13: 5000.2248 | R13: 1531.7934 | S13: 1849.9052 | T13: - | U13: - | V13: - | W13: - | X13: - | Y13: - | Z13: - | AA13: - | AB13: - | AC13: - | AD13: - | AE13: -
A14: rwro_consistent-6.2.0-506,112,52-2100-202605210218 | B14: 1025.3681 | C14: 23825.236 | D14: 15233.475 | E14: 8070.1276 | F14: 8091.3449 | G14: 8505.9461 | H14: 6727.7783 | I14: 69.582848 | J14: - | K14: - | L14: - | M14: - | N14: - | O14: - | P14: - | Q14: 5010.0183 | R14: 1553.8995 | S14: 1942.0283 | T14: - | U14: - | V14: - | W14: - | X14: - | Y14: - | Z14: - | AA14: - | AB14: - | AC14: - | AD14: - | AE14: -
A15: rwro_consistent-6.2.0-506,112,52-2400-202605210023 | B15: 956.25216 | C15: 32659.542 | D15: 11665.445 | E15: 8089.1044 | F15: 8062.3862 | G15: 8659.0259 | H15: 7335.1537 | I15: 71.364608 | J15: - | K15: - | L15: - | M15: - | N15: - | O15: - | P15: - | Q15: 5003.3869 | R15: 1696.2806 | S15: 1959.3585 | T15: - | U15: - | V15: - | W15: - | X15: - | Y15: - | Z15: - | AA15: - | AB15: - | AC15: - | AD15: - | AE15: -
A16: rwro_consistent-6.2.0-506,112,52-2700-202605210241 | B16: 926.48653 | C16: 33151.156 | D16: 14864.564 | E16: 8067.3014 | F16: 8104.96 | G16: 8458.6701 | H16: 7232.4383 | I16: 69.128192 | J16: - | K16: - | L16: - | M16: - | N16: - | O16: - | P16: - | Q16: 4990.9801 | R16: 1587.8963 | S16: 1879.7937 | T16: - | U16: - | V16: - | W16: - | X16: - | Y16: - | Z16: - | AA16: - | AB16: - | AC16: - | AD16: - | AE16: -
A17: rwro_consistent-6.2.0-506,112,52-3000-202605210046 | B17: 1168.8018 | C17: 22701.99 | D17: 15348.158 | E17: 8087.4947 | F17: 8074.0762 | G17: 8468.4923 | H17: 7405.5229 | I17: 69.287936 | J17: - | K17: - | L17: - | M17: - | N17: - | O17: - | P17: - | Q17: 4991.8239 | R17: 1605.0463 | S17: 1871.6221 | T17: - | U17: - | V17: - | W17: - | X17: - | Y17: - | Z17: - | AA17: - | AB17: - | AC17: - | AD17: - | AE17: -
A18: rwro_none-6.2.0-506,112,52-1-202605201840 | B18: 268.52557 | C18: 16851.616 | D18: 1422.8972 | E18: 1548.1979 | F18: 1436.7375 | G18: 2711.167 | H18: 1349.0504 | I18: 69.77536 | J18: - | K18: - | L18: - | M18: - | N18: - | O18: - | P18: - | Q18: 920.09677 | R18: 873.94304 | S18: 917.12717 | T18: - | U18: - | V18: - | W18: - | X18: - | Y18: - | Z18: - | AA18: - | AB18: - | AC18: - | AD18: - | AE18: -
... A50: rwro_optimized_heap-6.2.0-506,112,52-3000-202605211228 | B50: 1191.0963 | C50: 22556.189 | D50: 14994.944 | E50: 8127.4839 | F50: 8060.2767 | G50: 8252.8256 | H50: 7499.8047 | I50: 70.455296 | J50: - | K50: - | L50: - | M50: - | N50: - | O50: - | P50: - | Q50: 5012.5455 | R50: 1529.9625 | S50: 1710.3176 | T50: - | U50: - | V50: - | W50: - | X50: - | Y50: - | Z50: - | AA50: - | AB50: - | AC50: - | AD50: - | AE50: -
A51: parallel_command-6.3.0-523,127,67-1-202606070759 | B51: 248.06605 | C51: 5687.3943 | D51: 1370.4929 | E51: 2517.9791 | F51: 2238.3247 | G51: 2537.6195 | H51: 845.42259 | I51: 66.6624 | J51: 1097.3389 | K51: 1998.8603 | L51: 2591.1951 | M51: 1370.4929 | N51: - | O51: 2517.9791 | P51: 2238.3247 | Q51: 1040.5437 | R51: 691.10579 | S51: 805.96992 | T51: 150.5321 | U51: 143.40096 | V51: 130.53542 | W51: 139.44013 | X51: 132.37862 | Y51: 149.13536 | Z51: 10.973184 | AA51: 10.719232 | AB51: 10.764288 | AC51: 12.640256 | AD51: 11.030528 | AE51: 10.534912
A52: parallel_command-6.3.0-523,127,67-300-202606070824 | B52: 617.3655 | C52: 12878.295 | D52: 3466.6332 | E52: 5549.867 | F52: 5412.1923 | G52: 2354.5938 | H52: 831.8976 | I52: 66.277376 | J52: 10441.261 | K52: 1326.2889 | L52: 1110.7451 | M52: 3466.6332 | N52: - | O52: 5549.867 | P52: 5412.1923 | Q52: 913.69882 | R52: 679.46906 | S52: 761.42592 | T52: 134.59866 | U52: 142.79885 | V52: 129.81043 | W52: 144.83866 | X52: 133.47226 | Y52: 146.37875 | Z52: 12.419072 | AA52: 11.4688 | AB52: 10.805248 | AC52: 10.293248 | AD52: 11.014144 | AE52: 10.276864
A53: parallel_command-6.3.0-523,127,67-600-202606070849 | B53: 1117.3274 | C53: 23347.028 | D53: 3779.3505 | E53: 6590.4067 | F53: 5852.6925 | G53: 2414.334 | H53: 821.72723 | I53: 65.871872 | J53: 10454.729 | K53: 11697.377 | L53: 1194.922 | M53: 3779.3505 | N53: - | O53: 6590.4067 | P53: 5852.6925 | Q53: 965.82861 | R53: 710.84851 | S53: 737.65683 | T53: 137.77306 | U53: 137.78125 | V53: 132.73498 | W53: 143.36 | X53: 131.81338 | Y53: 138.26458 | Z53: 12.43136 | AA53: 11.362304 | AB53: 10.756096 | AC53: 10.289152 | AD53: 10.752 | AE53: 10.28096
A54: parallel_command-6.3.0-523,127,67-900-202606070914 | B54: 1928.663 | C54: 13524.185 | D54: 5311.7133 | E54: 8192.7004 | F54: 6418.4115 | G54: 2412.9823 | H54: 865.35373 | I54: 66.248704 | J54: 1382.7154 | K54: 10457.223 | L54: 1684.2465 | M54: 5311.7133 | N54: - | O54: 8192.7004 | P54: 6418.4115 | Q54: 933.51526 | R54: 712.02406 | S54: 767.44294 | T54: 147.4519 | U54: 155.3408 | V54: 140.57472 | W54: 143.28218 | X54: 138.66189 | Y54: 140.04224 | Z54: 12.47232 | AA54: 11.399168 | AB54: 10.752 | AC54: 10.285056 | AD54: 10.764288 | AE54: 10.575872
A55: parallel_command-6.3.0-523,127,67-1200-202606070939 | B55: 984.15821 | C55: 13427.732 | D55: 4647.5141 | E55: 8193.0977 | F55: 8217.0225 | G55: 2407.2192 | H55: 849.70291 | I55: 69.259264 | J55: 1211.8835 | K55: 11071.185 | L55: 1144.6641 | M55: 4647.5141 | N55: - | O55: 8193.0977 | P55: 8217.0225 | Q55: 1002.6803 | R55: 697.2375 | S55: 707.30138 | T55: 142.48346 | U55: 146.19443 | V55: 137.47814 | W55: 140.42726 | X55: 133.15686 | Y55: 149.96275 | Z55: 13.963264 | AA55: 11.137024 | AB55: 10.752 | AC55: 12.382208 | AD55: 10.747904 | AE55: 10.276864
A56: parallel_command-6.3.0-523,127,67-1500-202606071005 | B56: 1174.442 | C56: 13992.559 | D56: 6656.7987 | E56: 8173.5107 | F56: 8170.3977 | G56: 2553.6348 | H56: 850.87437 | I56: 66.015232 | J56: 11148.62 | K56: 1164.2798 | L56: 1679.659 | M56: 6656.7987 | N56: - | O56: 8173.5107 | P56: 8170.3977 | Q56: 1046.4502 | R56: 737.82477 | S56: 769.35987 | T56: 144.60928 | U56: 140.52966 | V56: 133.86138 | W56: 150.16755 | X56: 136.97434 | Y56: 144.73216 | Z56: 12.537856 | AA56: 11.378688 | AB56: 10.764288 | AC56: 10.289152 | AD56: 10.752 | AE56: 10.293248
A57: parallel_command-6.3.0-523,127,67-1800-202606071030 | B57: 1063.3175 | C57: 13943.841 | D57: 6951.0881 | E57: 8154.7633 | F57: 8059.007 | G57: 2484.8753 | H57: 1075.1427 | I57: 66.41664 | J57: 1267.5686 | K57: 10958.729 | L57: 1717.5429 | M57: 6951.0881 | N57: - | O57: 8154.7633 | P57: 8059.007 | Q57: 995.24198 | R57: 718.69235 | S57: 770.94093 | T57: 144.72397 | U57: 143.52384 | V57: 226.00909 | W57: 138.86259 | X57: 131.76422 | Y57: 290.25894 | Z57: 12.828672 | AA57: 11.48928 | AB57: 10.784768 | AC57: 10.28096 | AD57: 10.756096 | AE57: 10.276864
A58: parallel_command-6.3.0-523,127,67-2100-202606071055 | B58: 1239.8141 | C58: 22898.565 | D58: 7238.1932 | E58: 8125.9684 | F58: 8074.5226 | G58: 2451.4191 | H58: 840.17562 | I58: 66.08896 | J58: 10774.942 | K58: 1693.2905 | L58: 10430.333 | M58: 7238.1932 | N58: - | O58: 8125.9684 | P58: 8074.5226 | Q58: 984.79309 | R58: 720.80589 | S58: 745.82016 | T58: 146.75558 | U58: 136.67533 | V58: 137.40442 | W58: 144.20378 | X58: 134.62733 | Y58: 140.50918 | Z58: 12.263424 | AA58: 11.661312 | AB58: 10.821632 | AC58: 10.293248 | AD58: 10.760192 | AE58: 10.289152
A59: parallel_command-6.3.0-523,127,67-2400-202606071120 | B59: 1182.4824 | C59: 32955.843 | D59: 8759.4844 | E59: 8135.4465 | F59: 8114.4873 | G59: 2448.1792 | H59: 837.6361 | I59: 65.753088 | J59: 10680.865 | K59: 11632.722 | L59: 10642.256 | M59: 8759.4844 | N59: - | O59: 8135.4465 | P59: 8114.4873 | Q59: 985.55085 | R59: 711.10656 | S59: 751.52179 | T59: 139.19846 | U59: 140.0873 | V59: 148.65613 | W59: 139.0551 | X59: 137.57645 | Y59: 133.06266 | Z59: 12.32896 | AA59: 11.239424 | AB59: 10.752 | AC59: 10.276864 | AD59: 10.79296 | AE59: 10.36288
A60: parallel_command-6.3.0-523,127,67-2700-202606071146 | B60: 1242.7387 | C60: 22299.591 | D60: 9047.7855 | E60: 8115.8513 | F60: 8120.148 | G60: 2503.6308 | H60: 855.40864 | I60: 66.048 | J60: 1154.3962 | K60: 10613.973 | L60: 10531.222 | M60: 9047.7855 | N60: - | O60: 8115.8513 | P60: 8120.148 | Q60: 1037.7052 | R60: 717.76666 | S60: 748.15898 | T60: 137.40851 | U60: 169.81606 | V60: 130.64602 | W60: 144.98611 | X60: 134.69286 | Y60: 137.85907 | Z60: 12.353536 | AA60: 11.476992 | AB60: 10.81344 | AC60: 10.293248 | AD60: 10.768384 | AE60: 10.3424
A61: parallel_command-6.3.0-523,127,67-3000-202606071211 | B61: 1080.6108 | C61: 32838.156 | D61: 8011.4319 | E61: 8128.6267 | F61: 8059.8794 | G61: 2514.1862 | H61: 857.13715 | I61: 66.318336 | J61: 10503.561 | K61: 11709.153 | L61: 10625.442 | M61: 8011.4319 | N61: - | O61: 8128.6267 | P61: 8059.8794 | Q61: 1020.9976 | R61: 733.34374 | S61: 759.84486 | T61: 135.52435 | U61: 146.2313 | V61: 143.93344 | W61: 141.67245 | X61: 132.1984 | Y61: 157.57722 | Z61: 12.57472 | AA61: 11.599872 | AB61: 10.756096 | AC61: 10.289152 | AD61: 10.81344 | AE61: 10.285056
A62: get_by_prefix_1-6.3.0-528,133,73-1-202606200213 | B62: 202.53901 | C62: 22112.772 | D62: 1466.9783 | E62: 5102.5224 | F62: 5051.0397 | G62: 7418.6465 | H62: 870.94477 | I62: 64.241664 | J62: 1232.8428 | K62: 10435.654 | L62: 10444.276 | M62: 1466.9783 | N62: - | O62: 5102.5224 | P62: 5051.0397 | Q62: 4961.9354 | R62: 1227.1043 | S62: 1229.6069 | T62: 171.68794 | U62: 148.15642 | V62: 138.79296 | W62: 141.0048 | X62: 133.20192 | Y62: 138.10074 | Z62: 10.801152 | AA62: 9.633792 | AB62: 11.214848 | AC62: 10.674176 | AD62: 11.214848 | AE62: 10.702848
... A120: choreography-6.3.0-528,133,73-3000-202606261826 | B120: 266.56358 | C120: 36801.503 | D120: 9091.8543 | E120: 8121.4833 | F120: 8118.1737 | G120: 2276.4257 | H120: 825.72493 | I120: 62.496768 | J120: 14370.324 | K120: 11404.624 | L120: 11026.555 | M120: 9091.8543 | N120: - | O120: 8121.4833 | P120: 8118.1737 | Q120: 937.63584 | R120: 669.86803 | S120: 668.92186 | T120: 133.68115 | U120: 138.07616 | V120: 132.35405 | W120: 145.58413 | X120: 135.6759 | Y120: 140.35354 | Z120: 11.38688 | AA120: 12.357632 | AB120: 9.940992 | AC120: 9.457664 | AD120: 9.924608 | AE120: 9.428992

Sheet Throttle_%
A1: RunID | B1: im | C1: kafka | D1: orch-a | E1: part-b | F1: part-c | G1: rf | H1: mongo | I1: redis | J1: kafka-0 | K1: kafka-1 | L1: kafka-2 | M1: orch-a-0 | N1: orch-a-1 | O1: part-b-0 | P1: part-c-0 | Q1: rf-a-0 | R1: rf-b-0 | S1: rf-c-0 | T1: mongo-a-0 | U1: mongo-a-1 | V1: mongo-b-0 | W1: mongo-b-1 | X1: mongo-c-0 | Y1: mongo-c-1 | Z1: redis-a-0 | AA1: redis-a-1 | AB1: redis-b-0 | AC1: redis-b-1 | AD1: redis-c-0 | AE1: redis-c-1
A2: simple-6.2.0-476,82,23-50-202605081142 | B2: 0 | C2: 17.117117 | D2: 0.2248033 | E2: 0 | F2: 0.036363636 | G2: 0 | H2: 16.594695 | I2: 0 | J2: - | K2: - | L2: - | M2: - | N2: - | O2: - | P2: - | Q2: - | R2: - | S2: - | T2: - | U2: - | V2: - | W2: - | X2: - | Y2: - | Z2: - | AA2: - | AB2: - | AC2: - | AD2: - | AE2: -
A3: simple-6.2.0-476,82,23-75-202605081207 | B3: 0 | C3: 16.135559 | D3: 0.18839488 | E3: 0 | F3: 0.077011937 | G3: 0 | H3: 16.141002 | I3: 0 | J3: - | K3: - | L3: - | M3: - | N3: - | O3: - | P3: - | Q3: - | R3: - | S3: - | T3: - | U3: - | V3: - | W3: - | X3: - | Y3: - | Z3: - | AA3: - | AB3: - | AC3: - | AD3: - | AE3: -
A4: simple-6.2.0-476,82,23-150-202605081232 | B4: 0.037369208 | C4: 16.897507 | D4: 0.95895666 | E4: 0.18181818 | F4: 0.07160759 | G4: 0 | H4: 17.017438 | I4: 0 | J4: - | K4: - | L4: - | M4: - | N4: - | O4: - | P4: - | Q4: - | R4: - | S4: - | T4: - | U4: - | V4: - | W4: - | X4: - | Y4: - | Z4: - | AA4: - | AB4: - | AC4: - | AD4: - | AE4: -
A5: simple-6.2.0-476,82,23-200-202605081502 | B5: 0.036630037 | C5: 16.134454 | D5: 3.2834732 | E5: 0.42253521 | F5: 0.2268431 | G5: 0 | H5: 17.34143 | I5: 0 | J5: - | K5: - | L5: - | M5: - | N5: - | O5: - | P5: - | Q5: - | R5: - | S5: - | T5: - | U5: - | V5: - | W5: - | X5: - | Y5: - | Z5: - | AA5: - | AB5: - | AC5: - | AD5: - | AE5: -
A6: simple-6.2.0-476,82,23-30000-202605190912 | B6: 0.68519223 | C6: 16.990006 | D6: 4.1929499 | E6: 3.0706622 | F6: 2.3230088 | G6: 0 | H6: 0 | I6: 0 | J6: - | K6: - | L6: - | M6: - | N6: - | O6: - | P6: - | Q6: - | R6: - | S6: - | T6: - | U6: - | V6: - | W6: - | X6: - | Y6: - | Z6: - | AA6: - | AB6: - | AC6: - | AD6: - | AE6: -
A7: rwro_consistent-6.2.0-506,112,52-1-202605202252 | B7: 0 | C7: 7.2689341 | D7: 0 | E7: 0 | F7: 0 | G7: - | H7: 0 | I7: - | J7: - | K7: - | L7: - | M7: - | N7: - | O7: - | P7: - | Q7: 0 | R7: 0 | S7: 0 | T7: - | U7: - | V7: - | W7: - | X7: - | Y7: - | Z7: - | AA7: - | AB7: - | AC7: - | AD7: - | AE7: -
A8: rwro_consistent-6.2.0-506,112,52-300-202605210109 | B8: 0.34168565 | C8: 8.1193982 | D8: 0 | E8: 0.1039501 | F8: 0.29017048 | G8: - | H8: 0.028431707 | I8: - | J8: - | K8: - | L8: - | M8: - | N8: - | O8: - | P8: - | Q8: 0 | R8: 0 | S8: 0 | T8: - | U8: - | V8: - | W8: - | X8: - | Y8: - | Z8: - | AA8: - | AB8: - | AC8: - | AD8: - | AE8: -
A9: rwro_consistent-6.2.0-506,112,52-600-202605202315 | B9: 0.42857143 | C9: 7.7296569 | D9: 0 | E9: 0.36390102 | F9: 0.62339567 | G9: - | H9: 0.054911636 | I9: - | J9: - | K9: - | L9: - | M9: - | N9: - | O9: - | P9: - | Q9: 0 | R9: 0 | S9: 0 | T9: - | U9: - | V9: - | W9: - | X9: - | Y9: - | Z9: - | AA9: - | AB9: - | AC9: - | AD9: - | AE9: -
A10: rwro_consistent-6.2.0-506,112,52-900-202605210132 | B10: 0.78154075 | C10: 8.2579065 | D10: 0 | E10: 0.63861758 | F10: 1.2285927 | G10: - | H10: 0.06195652 | I10: - | J10: - | K10: - | L10: - | M10: - | N10: - | O10: - | P10: - | Q10: 0 | R10: 0 | S10: 0 | T10: - | U10: - | V10: - | W10: - | X10: - | Y10: - | Z10: - | AA10: - | AB10: - | AC10: - | AD10: - | AE10: -
A11: rwro_consistent-6.2.0-506,112,52-1200-202605202337 | B11: 0.61491161 | C11: 8.3261613 | D11: 0 | E11: 0.28591851 | F11: 0.59413294 | G11: - | H11: 0.062753385 | I11: - | J11: - | K11: - | L11: - | M11: - | N11: - | O11: - | P11: - | Q11: 0 | R11: 0 | S11: 0 | T11: - | U11: - | V11: - | W11: - | X11: - | Y11: - | Z11: - | AA11: - | AB11: - | AC11: - | AD11: - | AE11: -
A12: rwro_consistent-6.2.0-506,112,52-1500-202605210155 | B12: 0.29861889 | C12: 8.0091819 | D12: 0 | E12: 0.22115739 | F12: 0.90466249 | G12: - | H12: 0.06800408 | I12: - | J12: - | K12: - | L12: - | M12: - | N12: - | O12: - | P12: - | Q12: 0 | R12: 0 | S12: 0 | T12: - | U12: - | V12: - | W12: - | X12: - | Y12: - | Z12: - | AA12: - | AB12: - | AC12: - | AD12: - | AE12: -
A13: rwro_consistent-6.2.0-506,112,52-1800-202605210000 | B13: 0.46001415 | C13: 8.4065779 | D13: 0.038654813 | E13: 0.21715527 | F13: 2.0477816 | G13: - | H13: 0.074316234 | I13: - | J13: - | K13: - | L13: - | M13: - | N13: - | O13: - | P13: - | Q13: 0 | R13: 0 | S13: 0 | T13: - | U13: - | V13: - | W13: - | X13: - | Y13: - | Z13: - | AA13: - | AB13: - | AC13: - | AD13: - | AE13: -
A14: rwro_consistent-6.2.0-506,112,52-2100-202605210218 | B14: 0.69065794 | C14: 8.6623438 | D14: 0.035803795 | E14: 0.41952708 | F14: 2.3853895 | G14: - | H14: 0.087272516 | I14: - | J14: - | K14: - | L14: - | M14: - | N14: - | O14: - | P14: - | Q14: 0 | R14: 0 | S14: 0 | T14: - | U14: - | V14: - | W14: - | X14: - | Y14: - | Z14: - | AA14: - | AB14: - | AC14: - | AD14: - | AE14: -
A15: rwro_consistent-6.2.0-506,112,52-2400-202605210023 | B15: 0.58884655 | C15: 8.555358 | D15: 0.038431975 | E15: 0.86385625 | F15: 3.9548023 | G15: - | H15: 0.10613723 | I15: - | J15: - | K15: - | L15: - | M15: - | N15: - | O15: - | P15: - | Q15: 0 | R15: 0 | S15: 0 | T15: - | U15: - | V15: - | W15: - | X15: - | Y15: - | Z15: - | AA15: - | AB15: - | AC15: - | AD15: - | AE15: -
A16: rwro_consistent-6.2.0-506,112,52-2700-202605210241 | B16: 0.55555556 | C16: 9.1281563 | D16: 0.037174721 | E16: 0.34039334 | F16: 3.5262553 | G16: - | H16: 0.11829274 | I16: - | J16: - | K16: - | L16: - | M16: - | N16: - | O16: - | P16: - | Q16: 0 | R16: 0 | S16: 0 | T16: - | U16: - | V16: - | W16: - | X16: - | Y16: - | Z16: - | AA16: - | AB16: - | AC16: - | AD16: - | AE16: -
A17: rwro_consistent-6.2.0-506,112,52-3000-202605210046 | B17: 1.0475122 | C17: 8.2578552 | D17: 0.15203345 | E17: 1.172466 | F17: 3.5538353 | G17: - | H17: 0.17993978 | I17: - | J17: - | K17: - | L17: - | M17: - | N17: - | O17: - | P17: - | Q17: 0 | R17: 0 | S17: 0 | T17: - | U17: - | V17: - | W17: - | X17: - | Y17: - | Z17: - | AA17: - | AB17: - | AC17: - | AD17: - | AE17: -
A18: rwro_none-6.2.0-506,112,52-1-202605201840 | B18: 0 | C18: 7.1524352 | D18: 0 | E18: 0 | F18: 0 | G18: - | H18: 0 | I18: - | J18: - | K18: - | L18: - | M18: - | N18: - | O18: - | P18: - | Q18: 0 | R18: 0 | S18: 0 | T18: - | U18: - | V18: - | W18: - | X18: - | Y18: - | Z18: - | AA18: - | AB18: - | AC18: - | AD18: - | AE18: -
... A50: rwro_optimized_heap-6.2.0-506,112,52-3000-202605211228 | B50: 0.069565217 | C50: 8.8127182 | D50: 0.1026694 | E50: 0.74766355 | F50: 3.4048349 | G50: - | H50: 0.21111491 | I50: - | J50: - | K50: - | L50: - | M50: - | N50: - | O50: - | P50: - | Q50: 0 | R50: 0 | S50: 0 | T50: - | U50: - | V50: - | W50: - | X50: - | Y50: - | Z50: - | AA50: - | AB50: - | AC50: - | AD50: - | AE50: -
A51: parallel_command-6.3.0-523,127,67-1-202606070759 | B51: 0 | C51: 7.4323013 | D51: 0 | E51: 0 | F51: 0 | G51: 0 | H51: 0 | I51: - | J51: 11.176049 | K51: 5.6580737 | L51: 5.4627816 | M51: 0 | N51: - | O51: 0 | P51: 0 | Q51: 0 | R51: 0 | S51: 0 | T51: 0 | U51: 0 | V51: 0 | W51: 0 | X51: 0 | Y51: 0 | Z51: - | AA51: - | AB51: - | AC51: - | AD51: - | AE51: -
A52: parallel_command-6.3.0-523,127,67-300-202606070824 | B52: 0.67618332 | C52: 7.2584265 | D52: 0 | E52: 0 | F52: 0 | G52: 0 | H52: 0 | I52: - | J52: 6.1205719 | K52: 6.0599737 | L52: 9.594734 | M52: 0 | N52: - | O52: 0 | P52: 0 | Q52: 0 | R52: 0 | S52: 0 | T52: 0 | U52: 0 | V52: 0 | W52: 0 | X52: 0 | Y52: 0 | Z52: - | AA52: - | AB52: - | AC52: - | AD52: - | AE52: -
A53: parallel_command-6.3.0-523,127,67-600-202606070849 | B53: 1.0180995 | C53: 7.1676183 | D53: 0 | E53: 0.077160494 | F53: 0 | G53: 0 | H53: 0 | I53: - | J53: 5.949455 | K53: 9.6689448 | L53: 5.8844552 | M53: 0 | N53: - | O53: 0.077160494 | P53: 0 | Q53: 0 | R53: 0 | S53: 0 | T53: 0 | U53: 0 | V53: 0 | W53: 0 | X53: 0 | Y53: 0 | Z53: - | AA53: - | AB53: - | AC53: - | AD53: - | AE53: -
A54: parallel_command-6.3.0-523,127,67-900-202606070914 | B54: 0.53991516 | C54: 7.5530225 | D54: 0 | E54: 0.1447178 | F54: 0 | G54: 0 | H54: 0 | I54: - | J54: 6.2738471 | K54: 6.0842793 | L54: 10.300941 | M54: 0 | N54: - | O54: 0.1447178 | P54: 0 | Q54: 0 | R54: 0 | S54: 0 | T54: 0 | U54: 0 | V54: 0 | W54: 0 | X54: 0 | Y54: 0 | Z54: - | AA54: - | AB54: - | AC54: - | AD54: - | AE54: -
A55: parallel_command-6.3.0-523,127,67-1200-202606070939 | B55: 1.1741683 | C55: 7.4265367 | D55: 0 | E55: 0.37481259 | F55: 0.069589422 | G55: 0 | H55: 0 | I55: - | J55: 6.6565584 | K55: 6.2074799 | L55: 9.4155717 | M55: 0 | N55: - | O55: 0.37481259 | P55: 0.069589422 | Q55: 0 | R55: 0 | S55: 0 | T55: 0 | U55: 0 | V55: 0 | W55: 0 | X55: 0 | Y55: 0 | Z55: - | AA55: - | AB55: - | AC55: - | AD55: - | AE55: -
A56: parallel_command-6.3.0-523,127,67-1500-202606071005 | B56: 1.6332591 | C56: 7.7983477 | D56: 0 | E56: 0.11890606 | F56: 0.26070764 | G56: 0 | H56: 0 | I56: - | J56: 6.638266 | K56: 7.0094021 | L56: 9.747375 | M56: 0 | N56: - | O56: 0.11890606 | P56: 0.26070764 | Q56: 0 | R56: 0 | S56: 0 | T56: 0 | U56: 0 | V56: 0 | W56: 0 | X56: 0 | Y56: 0 | Z56: - | AA56: - | AB56: - | AC56: - | AD56: - | AE56: -
A57: parallel_command-6.3.0-523,127,67-1800-202606071030 | B57: 1.4264264 | C57: 7.3459078 | D57: 0 | E57: 0.4173913 | F57: 0.21134202 | G57: 0 | H57: 0 | I57: - | J57: 6.3376607 | K57: 8.961318 | L57: 6.7387446 | M57: 0 | N57: - | O57: 0.4173913 | P57: 0.21134202 | Q57: 0 | R57: 0 | S57: 0 | T57: 0 | U57: 0 | V57: 0 | W57: 0 | X57: 0 | Y57: 0 | Z57: - | AA57: - | AB57: - | AC57: - | AD57: - | AE57: -
A58: parallel_command-6.3.0-523,127,67-2100-202606071055 | B58: 1.0992908 | C58: 7.6208642 | D58: 0 | E58: 0.03705076 | F58: 0.56732224 | G58: 0 | H58: 0 | I58: - | J58: 6.8092814 | K58: 6.3452961 | L58: 9.7080151 | M58: 0 | N58: - | O58: 0.03705076 | P58: 0.56732224 | Q58: 0 | R58: 0 | S58: 0 | T58: 0 | U58: 0 | V58: 0 | W58: 0 | X58: 0 | Y58: 0 | Z58: - | AA58: - | AB58: - | AC58: - | AD58: - | AE58: -
A59: parallel_command-6.3.0-523,127,67-2400-202606071120 | B59: 1.0447761 | C59: 7.3919469 | D59: 0 | E59: 0.55643879 | F59: 0.76213398 | G59: 0 | H59: 0 | I59: - | J59: 6.4391385 | K59: 8.5909132 | L59: 7.145789 | M59: 0 | N59: - | O59: 0.55643879 | P59: 0.76213398 | Q59: 0 | R59: 0 | S59: 0 | T59: 0 | U59: 0 | V59: 0 | W59: 0 | X59: 0 | Y59: 0 | Z59: - | AA59: - | AB59: - | AC59: - | AD59: - | AE59: -
A60: parallel_command-6.3.0-523,127,67-2700-202606071146 | B60: 0.92332397 | C60: 7.8663052 | D60: 0 | E60: 0.80882353 | F60: 0.48721072 | G60: 0 | H60: 0 | I60: - | J60: 9.7545153 | K60: 7.1004375 | L60: 6.7439629 | M60: 0 | N60: - | O60: 0.80882353 | P60: 0.48721072 | Q60: 0 | R60: 0 | S60: 0 | T60: 0 | U60: 0 | V60: 0 | W60: 0 | X60: 0 | Y60: 0 | Z60: - | AA60: - | AB60: - | AC60: - | AD60: - | AE60: -
A61: parallel_command-6.3.0-523,127,67-3000-202606071211 | B61: 1.1219689 | C61: 7.8850778 | D61: 0 | E61: 0.61633282 | F61: 0.63837777 | G61: 0 | H61: 0 | I61: - | J61: 6.7327894 | K61: 9.8080103 | L61: 7.1144338 | M61: 0 | N61: - | O61: 0.61633282 | P61: 0.63837777 | Q61: 0 | R61: 0 | S61: 0 | T61: 0 | U61: 0 | V61: 0 | W61: 0 | X61: 0 | Y61: 0 | Z61: - | AA61: - | AB61: - | AC61: - | AD61: - | AE61: -
A62: get_by_prefix_1-6.3.0-528,133,73-1-202606200213 | B62: 0 | C62: =IFERROR(AVERAGE(J62:L62),"-") -> 7.5339928 | D62: =IFERROR(AVERAGE(M62:N62),"-") -> 0 | E62: =IFERROR(AVERAGE(O62:O62),"-") -> 0 | F62: =IFERROR(AVERAGE(P62:P62),"-") -> 0 | G62: =IFERROR(AVERAGE(Q62:S62),"-") -> 0 | H62: =IFERROR(AVERAGE(T62:Y62),"-") -> 0 | I62: =IFERROR(AVERAGE(Z62:AE62),"-") -> - | J62: 6.3557222 | K62: 10.271434 | L62: 5.9748226 | M62: 0 | N62: - | O62: 0 | P62: 0 | Q62: 0 | R62: 0 | S62: 0 | T62: 0 | U62: 0 | V62: 0 | W62: 0 | X62: 0 | Y62: 0 | Z62: - | AA62: - | AB62: - | AC62: - | AD62: - | AE62: -
A63: get_by_prefix_1-6.3.0-528,133,73-300-202606200235 | B63: 0 | C63: =IFERROR(AVERAGE(J63:L63),"-") -> 7.1824517 | D63: =IFERROR(AVERAGE(M63:N63),"-") -> 0 | E63: =IFERROR(AVERAGE(O63:O63),"-") -> 0 | F63: =IFERROR(AVERAGE(P63:P63),"-") -> 0 | G63: =IFERROR(AVERAGE(Q63:S63),"-") -> 0 | H63: =IFERROR(AVERAGE(T63:Y63),"-") -> 0 | I63: =IFERROR(AVERAGE(Z63:AE63),"-") -> - | J63: 6.4702568 | K63: 9.3704111 | L63: 5.7066872 | M63: 0 | N63: - | O63: 0 | P63: 0 | Q63: 0 | R63: 0 | S63: 0 | T63: 0 | U63: 0 | V63: 0 | W63: 0 | X63: 0 | Y63: 0 | Z63: - | AA63: - | AB63: - | AC63: - | AD63: - | AE63: -
A64: get_by_prefix_1-6.3.0-528,133,73-600-202606200257 | B64: 0 | C64: =IFERROR(AVERAGE(J64:L64),"-") -> 7.8148219 | D64: =IFERROR(AVERAGE(M64:N64),"-") -> 0 | E64: =IFERROR(AVERAGE(O64:O64),"-") -> 0 | F64: =IFERROR(AVERAGE(P64:P64),"-") -> 0 | G64: =IFERROR(AVERAGE(Q64:S64),"-") -> 0 | H64: =IFERROR(AVERAGE(T64:Y64),"-") -> 0 | I64: =IFERROR(AVERAGE(Z64:AE64),"-") -> - | J64: 6.7712287 | K64: 5.9992124 | L64: 10.674025 | M64: 0 | N64: - | O64: 0 | P64: 0 | Q64: 0 | R64: 0 | S64: 0 | T64: 0 | U64: 0 | V64: 0 | W64: 0 | X64: 0 | Y64: 0 | Z64: - | AA64: - | AB64: - | AC64: - | AD64: - | AE64: -
A65: get_by_prefix_1-6.3.0-528,133,73-900-202606200320 | B65: 0 | C65: =IFERROR(AVERAGE(J65:L65),"-") -> 7.5007521 | D65: =IFERROR(AVERAGE(M65:N65),"-") -> 0 | E65: =IFERROR(AVERAGE(O65:O65),"-") -> 0 | F65: =IFERROR(AVERAGE(P65:P65),"-") -> 0 | G65: =IFERROR(AVERAGE(Q65:S65),"-") -> 0 | H65: =IFERROR(AVERAGE(T65:Y65),"-") -> 0 | I65: =IFERROR(AVERAGE(Z65:AE65),"-") -> - | J65: 6.6331227 | K65: 6.18609 | L65: 9.6830435 | M65: 0 | N65: - | O65: 0 | P65: 0 | Q65: 0 | R65: 0 | S65: 0 | T65: 0 | U65: 0 | V65: 0 | W65: 0 | X65: 0 | Y65: 0 | Z65: - | AA65: - | AB65: - | AC65: - | AD65: - | AE65: -
A66: get_by_prefix_1-6.3.0-528,133,73-1200-202606200342 | B66: 0 | C66: =IFERROR(AVERAGE(J66:L66),"-") -> 7.5673946 | D66: =IFERROR(AVERAGE(M66:N66),"-") -> 0 | E66: =IFERROR(AVERAGE(O66:O66),"-") -> 0 | F66: =IFERROR(AVERAGE(P66:P66),"-") -> 0 | G66: =IFERROR(AVERAGE(Q66:S66),"-") -> 0 | H66: =IFERROR(AVERAGE(T66:Y66),"-") -> 0 | I66: =IFERROR(AVERAGE(Z66:AE66),"-") -> - | J66: 6.8533256 | K66: 6.2597722 | L66: 9.5890859 | M66: 0 | N66: - | O66: 0 | P66: 0 | Q66: 0 | R66: 0 | S66: 0 | T66: 0 | U66: 0 | V66: 0 | W66: 0 | X66: 0 | Y66: 0 | Z66: - | AA66: - | AB66: - | AC66: - | AD66: - | AE66: -
A67: get_by_prefix_1-6.3.0-528,133,73-1500-202606200404 | B67: 0 | C67: =IFERROR(AVERAGE(J67:L67),"-") -> 7.5200966 | D67: =IFERROR(AVERAGE(M67:N67),"-") -> 0 | E67: =IFERROR(AVERAGE(O67:O67),"-") -> 0 | F67: =IFERROR(AVERAGE(P67:P67),"-") -> 0 | G67: =IFERROR(AVERAGE(Q67:S67),"-") -> 0 | H67: =IFERROR(AVERAGE(T67:Y67),"-") -> 0 | I67: =IFERROR(AVERAGE(Z67:AE67),"-") -> - | J67: 5.9649963 | K67: 6.6585641 | L67: 9.9367295 | M67: 0 | N67: - | O67: 0 | P67: 0 | Q67: 0 | R67: 0 | S67: 0 | T67: 0 | U67: 0 | V67: 0 | W67: 0 | X67: 0 | Y67: 0 | Z67: - | AA67: - | AB67: - | AC67: - | AD67: - | AE67: -
A68: get_by_prefix_1-6.3.0-528,133,73-1800-202606200426 | B68: 0 | C68: =IFERROR(AVERAGE(J68:L68),"-") -> 7.1831332 | D68: =IFERROR(AVERAGE(M68:N68),"-") -> 0 | E68: =IFERROR(AVERAGE(O68:O68),"-") -> 0 | F68: =IFERROR(AVERAGE(P68:P68),"-") -> 0 | G68: =IFERROR(AVERAGE(Q68:S68),"-") -> 0 | H68: =IFERROR(AVERAGE(T68:Y68),"-") -> 0 | I68: =IFERROR(AVERAGE(Z68:AE68),"-") -> - | J68: 5.7774709 | K68: 6.4032523 | L68: 9.3686765 | M68: 0 | N68: - | O68: 0 | P68: 0 | Q68: 0 | R68: 0 | S68: 0 | T68: 0 | U68: 0 | V68: 0 | W68: 0 | X68: 0 | Y68: 0 | Z68: - | AA68: - | AB68: - | AC68: - | AD68: - | AE68: -
A69: get_by_prefix_1-6.3.0-528,133,73-2100-202606200448 | B69: 0 | C69: =IFERROR(AVERAGE(J69:L69),"-") -> 7.6708813 | D69: =IFERROR(AVERAGE(M69:N69),"-") -> 0 | E69: =IFERROR(AVERAGE(O69:O69),"-") -> 0 | F69: =IFERROR(AVERAGE(P69:P69),"-") -> 0 | G69: =IFERROR(AVERAGE(Q69:S69),"-") -> 0 | H69: =IFERROR(AVERAGE(T69:Y69),"-") -> 0 | I69: =IFERROR(AVERAGE(Z69:AE69),"-") -> - | J69: 6.5415561 | K69: 10.45333 | L69: 6.0177576 | M69: 0 | N69: - | O69: 0 | P69: 0 | Q69: 0 | R69: 0 | S69: 0 | T69: 0 | U69: 0 | V69: 0 | W69: 0 | X69: 0 | Y69: 0 | Z69: - | AA69: - | AB69: - | AC69: - | AD69: - | AE69: -
A70: get_by_prefix_1-6.3.0-528,133,73-2400-202606200511 | B70: 0 | C70: =IFERROR(AVERAGE(J70:L70),"-") -> 7.5905038 | D70: =IFERROR(AVERAGE(M70:N70),"-") -> 0 | E70: =IFERROR(AVERAGE(O70:O70),"-") -> 0 | F70: =IFERROR(AVERAGE(P70:P70),"-") -> 0 | G70: =IFERROR(AVERAGE(Q70:S70),"-") -> 0 | H70: =IFERROR(AVERAGE(T70:Y70),"-") -> 0 | I70: =IFERROR(AVERAGE(Z70:AE70),"-") -> - | J70: 6.6630733 | K70: 10.022736 | L70: 6.0857017 | M70: 0 | N70: - | O70: 0 | P70: 0 | Q70: 0 | R70: 0 | S70: 0 | T70: 0 | U70: 0 | V70: 0 | W70: 0 | X70: 0 | Y70: 0 | Z70: - | AA70: - | AB70: - | AC70: - | AD70: - | AE70: -
A71: get_by_prefix_1-6.3.0-528,133,73-2700-202606200532 | B71: 0.036764706 | C71: =IFERROR(AVERAGE(J71:L71),"-") -> 7.8758999 | D71: =IFERROR(AVERAGE(M71:N71),"-") -> 0 | E71: =IFERROR(AVERAGE(O71:O71),"-") -> 0 | F71: =IFERROR(AVERAGE(P71:P71),"-") -> 0 | G71: =IFERROR(AVERAGE(Q71:S71),"-") -> 0 | H71: =IFERROR(AVERAGE(T71:Y71),"-") -> 0 | I71: =IFERROR(AVERAGE(Z71:AE71),"-") -> - | J71: 10.125924 | K71: 6.7346508 | L71: 6.7671249 | M71: 0 | N71: - | O71: 0 | P71: 0 | Q71: 0 | R71: 0 | S71: 0 | T71: 0 | U71: 0 | V71: 0 | W71: 0 | X71: 0 | Y71: 0 | Z71: - | AA71: - | AB71: - | AC71: - | AD71: - | AE71: -
...

Sheet Regression
A1: TestID | B1: Scenario | C1: Exagon_ver | D1: Base CPU (idle) | E1: Marginal CPU (L) | F1: Transient overhead (extra) | G1: Overhead half-saturation const. (k) | H1: R2 | I1: Points Fitted/Total
A2: choreography-6.3.0-528,133,73 | B2: Coreografia | C2: dev-6.3.0-SNAPSHOT | D2: 1080.4504 | E2: 2.0515122 | F2: 7293.5427 | G2: 496.24068 | H2: 0.99894282 | I2: 11/11
A3: get_by_prefix_1-6.3.0-528,133,73 | B3: GetByPrefix 1 | C3: dev-6.3.0-SNAPSHOT | D3: 3125.0285 | E3: 1.5982087 | F3: 2875.0324 | G3: 511.78664 | H3: 0.99883903 | I3: 11/11
A4: get_by_prefix_27-6.3.0-528,133,73 | B4: GetByPrefix 27 | C4: dev-6.3.0-SNAPSHOT | D4: 3216.7452 | E4: 1.621545 | F4: 2869.9001 | G4: 612.66195 | H4: 0.99776569 | I4: 11/11
A5: get_by_prefix_703-6.3.0-528,133,73 | B5: GetByPrefix 703 | C5: dev-6.3.0-SNAPSHOT | D5: 3076.6549 | E5: 1.6090309 | F5: 2714.051 | G5: 377.58797 | H5: 0.99689658 | I5: 11/11
A6: parallel_command-6.3.0-523,127,67 | B6: Parallel Command | C6: dev-6.3.0-SNAPSHOT | D6: 970.34967 | E6: 2.7978704 | F6: 4863.0832 | G6: 240.69915 | H6: 0.99868039 | I6: 11/11
A7: rwro_none-6.2.0-506,112,52 | B7: RW/RO CacheNone | C7: dev-6.2.0-SNAPSHOT | D7: 846.83663 | E7: 4.9203404 | F7: 11622.358 | G7: 210.81673 | H7: 0.99660867 | I7: 8/11
A8: rwro_consistent-6.2.0-506,112,52 | B8: RW/RO Consistent | C8: dev-6.2.0-SNAPSHOT | D8: 858.63822 | E8: 4.1106623 | F8: 13176.43 | G8: 235.86876 | H8: 0.99721627 | I8: 11/11
A9: rwro_optimized_heap-6.2.0-506,112,52 | B9: RW/RO Optimized Heap | C9: dev-6.2.0-SNAPSHOT | D9: 808.70946 | E9: 3.7221734 | F9: 13067.751 | G9: 246.04646 | H9: 0.99847343 | I9: 11/11
A10: rwro_optimized_kvs-6.2.0-506,112,52 | B10: RW/RO Optimized KVS | C10: dev-6.2.0-SNAPSHOT | D10: 879.37866 | E10: 1.7303045 | F10: 21135.991 | G10: 480.26529 | H10: 0.99431578 | I10: 11/11
A11: simple-6.2.0-476,82,23 | B11: Saga Simples | C11: dev-6.2.0-SNAPSHOT | D11: 1000.0657 | E11: 2.7327462 | F11: 3343.8321 | G11: 86.591276 | H11: 0.9999839 | I11: 5/5
A12: simple-6.3.0-528,133,73 | B12: Saga Simples | C12: dev-6.3.0-SNAPSHOT | D12: 3322.9903 | E12: 1.6907737 | F12: 10206.652 | G12: 1234.777 | H12: 0.99911651 | I12: 15/15

Sheet Compare
